<?xml version="1.0" ?>
<!-- =================================================================================== -->
<!-- |    This document was autogenerated by xacro from /home/jade/Documents/Conarobot/Projects/Workflows/Doing/Conarobot_WS/src/realman_ros/realman_description/urdf/realman_65b_robot.urdf.xacro | -->
<!-- |    EDITING THIS FILE BY HAND IS NOT RECOMMENDED                                 | -->
<!-- =================================================================================== -->
<robot name="realman_65b_robot">
    <gazebo>
        <plugin filename="libgazebo_ros_control.so" name="ros_control">
            <robotNamespace>/realman</robotNamespace>
            <robotSimType>gazebo_ros_control/DefaultRobotHWSim</robotSimType>
            <legacyModeNS>true</legacyModeNS>
        </plugin>
        <plugin name="gazebo_ros_control">
            <robotNamespace>/</robotNamespace>
        </plugin>
    </gazebo>
    <!-- Links and joints for realman_65b -->
    <link name="base_link">
        <inertial>
            <origin rpy="0 0 0" xyz="-0.000433277303987328 -3.54664423471128E-05 0.0599427668933796" />
            <mass value="0.841070778135659" />
            <inertia ixx="0.0017261110801622" ixy="2.52746264980217E-06" ixz="-3.67690303614961E-05" iyy="0.00170987405835604" iyz="1.67996364994424E-06" izz="0.000904023422915791" />
        </inertial>
        <visual>
            <origin rpy="0 0 0" xyz="0 0 0" />
            <geometry>
                <mesh filename="package://realman_description/meshes/base_link.STL" />
            </geometry>
            <material name="">
                <color rgba="1 1 1 1" />
            </material>
        </visual>
        <collision>
            <origin rpy="0 0 0" xyz="0 0 0" />
            <geometry>
                <mesh filename="package://realman_description/meshes/base_link.STL" />
            </geometry>
        </collision>
    </link>
    <joint name="joint1" type="revolute">
        <origin rpy="0 0 0" xyz="0 0 0.2405" />
        <parent link="base_link" />
        <child link="Link1" />
        <axis xyz="0 0 1" />
        <limit effort="100" lower="-3.14" upper="3.14" velocity="1" />
        <dynamics damping="50" friction="1" />
    </joint>
    <link name="Link1">
        <inertial>
            <origin rpy="0 0 0" xyz="1.2226305431569E-08 0.0211079974844683 -0.0251854220842269" />
            <mass value="0.593563443690403" />
            <inertia ixx="0.00126614120341847" ixy="-1.294980943835E-08" ixz="-9.80120923066996E-09" iyy="0.00118168178300364" iyz="-0.00021121727444415" izz="0.00056135241627747" />
        </inertial>
        <visual>
            <origin rpy="0 0 0" xyz="0 0 0" />
            <geometry>
                <mesh filename="package://realman_description/meshes/Link1.STL" />
            </geometry>
            <material name="">
                <color rgba="1 1 1 1" />
            </material>
        </visual>
        <collision>
            <origin rpy="0 0 0" xyz="0 0 0" />
            <geometry>
                <mesh filename="package://realman_description/meshes/Link1.STL" />
            </geometry>
        </collision>
    </link>
    <joint name="joint2" type="revolute">
        <origin rpy="1.5708 -1.5708 0" xyz="0 0 0" />
        <parent link="Link1" />
        <child link="Link2" />
        <axis xyz="0 0 1" />
        <limit effort="100" lower="-2.268" upper="2.268" velocity="1" />
        <dynamics damping="50" friction="1" />
    </joint>
    <link name="Link2">
        <inertial>
            <origin rpy="0 0 0" xyz="0.152256463426163 4.75383656106654E-07 -0.00620260383607792" />
            <mass value="0.864175046869043" />
            <inertia ixx="0.00089150298478414" ixy="-2.23268489334765E-08" ixz="0.00156246461035015" iyy="0.00733754343083901" iyz="6.28110889329165E-09" izz="0.00697869103915473" />
        </inertial>
        <visual>
            <origin rpy="0 0 0" xyz="0 0 0" />
            <geometry>
                <mesh filename="package://realman_description/meshes/Link2.STL" />
            </geometry>
            <material name="">
                <color rgba="1 1 1 1" />
            </material>
        </visual>
        <collision>
            <origin rpy="0 0 0" xyz="0 0 0" />
            <geometry>
                <mesh filename="package://realman_description/meshes/Link2.STL" />
            </geometry>
        </collision>
    </link>
    <joint name="joint3" type="revolute">
        <origin rpy="0 0 1.5708" xyz="0.256 0 0" />
        <parent link="Link2" />
        <child link="Link3" />
        <axis xyz="0 0 1" />
        <limit effort="100" lower="-2.355" upper="2.355" velocity="1" />
        <dynamics damping="50" friction="1" />
    </joint>
    <link name="Link3">
        <inertial>
            <origin rpy="0 0 0" xyz="5.05312670989961E-06 -0.0595925663694732 0.010569069212336" />
            <mass value="0.289633681624654" />
            <inertia ixx="0.00063737100450158" ixy="-7.05261293649751E-08" ixz="-3.86643272239426E-08" iyy="0.00015648388095025" iyz="-0.00014461035994916" izz="0.000614178164773085" />
        </inertial>
        <visual>
            <origin rpy="0 0 0" xyz="0 0 0" />
            <geometry>
                <mesh filename="package://realman_description/meshes/Link3.STL" />
            </geometry>
            <material name="">
                <color rgba="1 1 1 1" />
            </material>
        </visual>
        <collision>
            <origin rpy="0 0 0" xyz="0 0 0" />
            <geometry>
                <mesh filename="package://realman_description/meshes/Link3.STL" />
            </geometry>
        </collision>
    </link>
    <joint name="joint4" type="revolute">
        <origin rpy="1.5708 0 0" xyz="0 -0.21 0" />
        <parent link="Link3" />
        <child link="Link4" />
        <axis xyz="0 0 1" />
        <limit effort="100" lower="-3.14" upper="3.14" velocity="1" />
        <dynamics damping="50" friction="1" />
    </joint>
    <link name="Link4">
        <inertial>
            <origin rpy="0 0 0" xyz="1.15516617405898E-06 -0.0180424468598241 -0.0215394748352687" />
            <mass value="0.239419768320061" />
            <inertia ixx="0.000285938919722783" ixy="3.07101359163101E-09" ixz="-2.21994118981953E-09" iyy="0.000262727540304212" iyz="4.4236583260078E-05" izz="0.000119888082791859" />
        </inertial>
        <visual>
            <origin rpy="0 0 0" xyz="0 0 0" />
            <geometry>
                <mesh filename="package://realman_description/meshes/Link4.STL" />
            </geometry>
            <material name="">
                <color rgba="1 1 1 1" />
            </material>
        </visual>
        <collision>
            <origin rpy="0 0 0" xyz="0 0 0" />
            <geometry>
                <mesh filename="package://realman_description/meshes/Link4.STL" />
            </geometry>
        </collision>
    </link>
    <joint name="joint5" type="revolute">
        <origin rpy="-1.5708 0 0" xyz="0 0 0" />
        <parent link="Link4" />
        <child link="Link5" />
        <axis xyz="0 0 1" />
        <limit effort="100" lower="-2.233" upper="2.233" velocity="1" />
        <dynamics damping="50" friction="1" />
    </joint>
    <link name="Link5">
        <inertial>
            <origin rpy="0 0 0" xyz="3.19794786262152E-06 -0.0593808368101458 0.00736804250989326" />
            <mass value="0.218799761431678" />
            <inertia ixx="0.000350540363914072" ixy="-3.41781619975602E-08" ixz="-1.77056457224373E-08" iyy="0.000104927867487581" iyz="-7.82431228461971E-05" izz="0.000334482418423629" />
        </inertial>
        <visual>
            <origin rpy="0 0 0" xyz="0 0 0" />
            <geometry>
                <mesh filename="package://realman_description/meshes/Link5.STL" />
            </geometry>
            <material name="">
                <color rgba="1 1 1 1" />
            </material>
        </visual>
        <collision>
            <origin rpy="0 0 0" xyz="0 0 0" />
            <geometry>
                <mesh filename="package://realman_description/meshes/Link5.STL" />
            </geometry>
        </collision>
    </link>
    <joint name="joint6" type="continuous">
        <origin rpy="1.5708 0 0" xyz="0 -0.144 0" />
        <parent link="Link5" />
        <child link="Link6" />
        <axis xyz="0 0 1" />
        <limit effort="100" lower="-6.28" upper="6.28" velocity="1" />
        <dynamics damping="50" friction="1" />
    </joint>
    <link name="Link6">
        <inertial>
            <origin rpy="0 0 0" xyz="0.000714234511756999 -0.000396718732824521 -0.0126723660946126" />
            <mass value="0.0649018034311231" />
            <inertia ixx="2.02766547502765E-05" ixy="-1.32505200276849E-06" ixz="-2.5845091522508E-08" iyy="1.87986725225022E-05" iyz="3.39471452125439E-09" izz="3.17885459163081E-05" />
        </inertial>
        <visual>
            <origin rpy="0 0 0" xyz="0 0 0" />
            <geometry>
                <mesh filename="package://realman_description/meshes/Link6.STL" />
            </geometry>
            <material name="">
                <color rgba="1 1 1 1" />
            </material>
        </visual>
        <collision>
            <origin rpy="0 0 0" xyz="0 0 0" />
            <geometry>
                <mesh filename="package://realman_description/meshes/Link6.STL" />
            </geometry>
        </collision>
    </link>
    <joint name="Link6-ee_link_fixed_joint" type="fixed">
        <origin rpy="0 0 1.5707963267948966" xyz="0 0 0.0289" />
        <parent link="Link6" />
        <child link="ee_link" />
    </joint>
    <link name="ee_link" />
    <transmission name="joint1_trans">
        <type>transmission_interface/SimpleTransmission</type>
        <joint name="joint1">
            <hardwareInterface>PositionJointInterface</hardwareInterface>
        </joint>
        <actuator name="joint1_motor">
            <mechanicalReduction>1</mechanicalReduction>
            <hardwareInterface>hardware_interface/EffortJointInterface</hardwareInterface>
        </actuator>
    </transmission>
    <transmission name="joint2_trans">
        <type>transmission_interface/SimpleTransmission</type>
        <joint name="joint2">
            <hardwareInterface>PositionJointInterface</hardwareInterface>
        </joint>
        <actuator name="joint2_motor">
            <mechanicalReduction>1</mechanicalReduction>
            <hardwareInterface>hardware_interface/EffortJointInterface</hardwareInterface>
        </actuator>
    </transmission>
    <transmission name="joint3_trans">
        <type>transmission_interface/SimpleTransmission</type>
        <joint name="joint3">
            <hardwareInterface>PositionJointInterface</hardwareInterface>
        </joint>
        <actuator name="joint3_motor">
            <mechanicalReduction>1</mechanicalReduction>
            <hardwareInterface>hardware_interface/EffortJointInterface</hardwareInterface>
        </actuator>
    </transmission>
    <transmission name="joint4_trans">
        <type>transmission_interface/SimpleTransmission</type>
        <joint name="joint4">
            <hardwareInterface>PositionJointInterface</hardwareInterface>
        </joint>
        <actuator name="joint4_motor">
            <mechanicalReduction>1</mechanicalReduction>
            <hardwareInterface>hardware_interface/EffortJointInterface</hardwareInterface>
        </actuator>
    </transmission>
    <transmission name="joint5_trans">
        <type>transmission_interface/SimpleTransmission</type>
        <joint name="joint5">
            <hardwareInterface>PositionJointInterface</hardwareInterface>
        </joint>
        <actuator name="joint5_motor">
            <mechanicalReduction>1</mechanicalReduction>
            <hardwareInterface>hardware_interface/EffortJointInterface</hardwareInterface>
        </actuator>
    </transmission>
    <transmission name="joint6_trans">
        <type>transmission_interface/SimpleTransmission</type>
        <joint name="joint6">
            <hardwareInterface>PositionJointInterface</hardwareInterface>
        </joint>
        <actuator name="joint6_motor">
            <mechanicalReduction>1</mechanicalReduction>
            <hardwareInterface>hardware_interface/EffortJointInterface</hardwareInterface>
        </actuator>
    </transmission>
    <gazebo reference="base_link">
        <selfCollide>true</selfCollide>
        <mu1 value="200000.0" />
        <mu2 value="200000.0" />
        <kp value="100000000.0" />
        <kd value="1.0" />
    </gazebo>
    <gazebo reference="Link1">
        <selfCollide>true</selfCollide>
    </gazebo>
    <gazebo reference="Link2">
        <selfCollide>true</selfCollide>
    </gazebo>
    <gazebo reference="Link3">
        <selfCollide>true</selfCollide>
    </gazebo>
    <gazebo reference="Link4">
        <selfCollide>true</selfCollide>
    </gazebo>
    <gazebo reference="Link5">
        <selfCollide>true</selfCollide>
    </gazebo>
    <gazebo reference="Link6">
        <selfCollide>true</selfCollide>
    </gazebo>
    <!-- construct the scene -->
    <link name="world" />
    <joint name="world_joint" type="fixed">
        <parent link="world" />
        <child link="base_link" />
        <origin rpy="0.0 0.0 0.0" xyz="0.0 0.0 0.0" />
    </joint>
</robot>

